2020-11-04 19:04:52,724 INFO MainThread :  * Running on http://127.0.0.1:5000/ (Press CTRL+C to quit)
2020-11-04 19:05:06,464 ERROR Thread-1 : Exception on /api/otb [GET]
Traceback (most recent call last):
  File "/mnt/c/Users/luisi/Desktop/cloe/api/env/lib/python3.7/site-packages/flask/app.py", line 2447, in wsgi_app
    response = self.full_dispatch_request()
  File "/mnt/c/Users/luisi/Desktop/cloe/api/env/lib/python3.7/site-packages/flask/app.py", line 1952, in full_dispatch_request
    rv = self.handle_user_exception(e)
  File "/mnt/c/Users/luisi/Desktop/cloe/api/env/lib/python3.7/site-packages/flask_cors/extension.py", line 165, in wrapped_function
    return cors_after_request(app.make_response(f(*args, **kwargs)))
  File "/mnt/c/Users/luisi/Desktop/cloe/api/env/lib/python3.7/site-packages/flask/app.py", line 1821, in handle_user_exception
    reraise(exc_type, exc_value, tb)
  File "/mnt/c/Users/luisi/Desktop/cloe/api/env/lib/python3.7/site-packages/flask/_compat.py", line 39, in reraise
    raise value
  File "/mnt/c/Users/luisi/Desktop/cloe/api/env/lib/python3.7/site-packages/flask/app.py", line 1950, in full_dispatch_request
    rv = self.dispatch_request()
  File "/mnt/c/Users/luisi/Desktop/cloe/api/env/lib/python3.7/site-packages/flask/app.py", line 1936, in dispatch_request
    return self.view_functions[rule.endpoint](**req.view_args)
  File "/mnt/c/Users/luisi/Desktop/cloe/api/env/lib/python3.7/site-packages/flask/views.py", line 89, in view
    return self.dispatch_request(*args, **kwargs)
  File "/mnt/c/Users/luisi/Desktop/cloe/api/env/lib/python3.7/site-packages/flask/views.py", line 163, in dispatch_request
    return meth(*args, **kwargs)
  File "/mnt/c/Users/luisi/Desktop/cloe/api/app/routes/otb.py", line 118, in get
    return make_response(simplejson.dumps(responseObject)), 200
  File "/mnt/c/Users/luisi/Desktop/cloe/api/env/lib/python3.7/site-packages/simplejson/__init__.py", line 395, in dumps
    return _default_encoder.encode(obj)
  File "/mnt/c/Users/luisi/Desktop/cloe/api/env/lib/python3.7/site-packages/simplejson/encoder.py", line 296, in encode
    chunks = self.iterencode(o, _one_shot=True)
  File "/mnt/c/Users/luisi/Desktop/cloe/api/env/lib/python3.7/site-packages/simplejson/encoder.py", line 378, in iterencode
    return _iterencode(o, 0)
  File "/mnt/c/Users/luisi/Desktop/cloe/api/env/lib/python3.7/site-packages/simplejson/encoder.py", line 273, in default
    o.__class__.__name__)
TypeError: Object of type datetime is not JSON serializable
2020-11-04 19:05:06,658 INFO Thread-1 : 127.0.0.1 - - [04/Nov/2020 19:05:06] "[35m[1mGET /api/otb?mercado=d&current_period=29-NOV-20 HTTP/1.1[0m" 500 -
2020-11-04 19:05:18,513 ERROR Thread-2 : Exception on /api/otb [GET]
Traceback (most recent call last):
  File "/mnt/c/Users/luisi/Desktop/cloe/api/env/lib/python3.7/site-packages/flask/app.py", line 2447, in wsgi_app
    response = self.full_dispatch_request()
  File "/mnt/c/Users/luisi/Desktop/cloe/api/env/lib/python3.7/site-packages/flask/app.py", line 1952, in full_dispatch_request
    rv = self.handle_user_exception(e)
  File "/mnt/c/Users/luisi/Desktop/cloe/api/env/lib/python3.7/site-packages/flask_cors/extension.py", line 165, in wrapped_function
    return cors_after_request(app.make_response(f(*args, **kwargs)))
  File "/mnt/c/Users/luisi/Desktop/cloe/api/env/lib/python3.7/site-packages/flask/app.py", line 1821, in handle_user_exception
    reraise(exc_type, exc_value, tb)
  File "/mnt/c/Users/luisi/Desktop/cloe/api/env/lib/python3.7/site-packages/flask/_compat.py", line 39, in reraise
    raise value
  File "/mnt/c/Users/luisi/Desktop/cloe/api/env/lib/python3.7/site-packages/flask/app.py", line 1950, in full_dispatch_request
    rv = self.dispatch_request()
  File "/mnt/c/Users/luisi/Desktop/cloe/api/env/lib/python3.7/site-packages/flask/app.py", line 1936, in dispatch_request
    return self.view_functions[rule.endpoint](**req.view_args)
  File "/mnt/c/Users/luisi/Desktop/cloe/api/env/lib/python3.7/site-packages/flask/views.py", line 89, in view
    return self.dispatch_request(*args, **kwargs)
  File "/mnt/c/Users/luisi/Desktop/cloe/api/env/lib/python3.7/site-packages/flask/views.py", line 163, in dispatch_request
    return meth(*args, **kwargs)
  File "/mnt/c/Users/luisi/Desktop/cloe/api/app/routes/otb.py", line 118, in get
    return make_response(simplejson.dumps(responseObject)), 200
  File "/mnt/c/Users/luisi/Desktop/cloe/api/env/lib/python3.7/site-packages/simplejson/__init__.py", line 395, in dumps
    return _default_encoder.encode(obj)
  File "/mnt/c/Users/luisi/Desktop/cloe/api/env/lib/python3.7/site-packages/simplejson/encoder.py", line 296, in encode
    chunks = self.iterencode(o, _one_shot=True)
  File "/mnt/c/Users/luisi/Desktop/cloe/api/env/lib/python3.7/site-packages/simplejson/encoder.py", line 378, in iterencode
    return _iterencode(o, 0)
  File "/mnt/c/Users/luisi/Desktop/cloe/api/env/lib/python3.7/site-packages/simplejson/encoder.py", line 273, in default
    o.__class__.__name__)
TypeError: Object of type datetime is not JSON serializable
2020-11-04 19:05:18,656 INFO Thread-2 : 127.0.0.1 - - [04/Nov/2020 19:05:18] "[35m[1mGET /api/otb?mercado=d&current_period=29-NOV-20 HTTP/1.1[0m" 500 -
2020-11-04 19:05:38,778 INFO MainThread :  * Running on http://127.0.0.1:5000/ (Press CTRL+C to quit)
2020-11-04 19:06:32,902 ERROR Thread-1 : Exception on /api/otb [GET]
Traceback (most recent call last):
  File "/mnt/c/Users/luisi/Desktop/cloe/api/env/lib/python3.7/site-packages/flask/app.py", line 2447, in wsgi_app
    response = self.full_dispatch_request()
  File "/mnt/c/Users/luisi/Desktop/cloe/api/env/lib/python3.7/site-packages/flask/app.py", line 1952, in full_dispatch_request
    rv = self.handle_user_exception(e)
  File "/mnt/c/Users/luisi/Desktop/cloe/api/env/lib/python3.7/site-packages/flask_cors/extension.py", line 165, in wrapped_function
    return cors_after_request(app.make_response(f(*args, **kwargs)))
  File "/mnt/c/Users/luisi/Desktop/cloe/api/env/lib/python3.7/site-packages/flask/app.py", line 1821, in handle_user_exception
    reraise(exc_type, exc_value, tb)
  File "/mnt/c/Users/luisi/Desktop/cloe/api/env/lib/python3.7/site-packages/flask/_compat.py", line 39, in reraise
    raise value
  File "/mnt/c/Users/luisi/Desktop/cloe/api/env/lib/python3.7/site-packages/flask/app.py", line 1950, in full_dispatch_request
    rv = self.dispatch_request()
  File "/mnt/c/Users/luisi/Desktop/cloe/api/env/lib/python3.7/site-packages/flask/app.py", line 1936, in dispatch_request
    return self.view_functions[rule.endpoint](**req.view_args)
  File "/mnt/c/Users/luisi/Desktop/cloe/api/env/lib/python3.7/site-packages/flask/views.py", line 89, in view
    return self.dispatch_request(*args, **kwargs)
  File "/mnt/c/Users/luisi/Desktop/cloe/api/env/lib/python3.7/site-packages/flask/views.py", line 163, in dispatch_request
    return meth(*args, **kwargs)
  File "/mnt/c/Users/luisi/Desktop/cloe/api/app/routes/otb.py", line 118, in get
    return make_response(simplejson.dumps(responseObject)), 200
  File "/mnt/c/Users/luisi/Desktop/cloe/api/env/lib/python3.7/site-packages/simplejson/__init__.py", line 395, in dumps
    return _default_encoder.encode(obj)
  File "/mnt/c/Users/luisi/Desktop/cloe/api/env/lib/python3.7/site-packages/simplejson/encoder.py", line 296, in encode
    chunks = self.iterencode(o, _one_shot=True)
  File "/mnt/c/Users/luisi/Desktop/cloe/api/env/lib/python3.7/site-packages/simplejson/encoder.py", line 378, in iterencode
    return _iterencode(o, 0)
  File "/mnt/c/Users/luisi/Desktop/cloe/api/env/lib/python3.7/site-packages/simplejson/encoder.py", line 273, in default
    o.__class__.__name__)
TypeError: Object of type datetime is not JSON serializable
2020-11-04 19:06:33,079 INFO Thread-1 : 127.0.0.1 - - [04/Nov/2020 19:06:33] "[35m[1mGET /api/otb?mercado=d&current_period=29-NOV-20 HTTP/1.1[0m" 500 -
2020-11-04 19:07:05,810 INFO MainThread :  * Running on http://127.0.0.1:5000/ (Press CTRL+C to quit)
2020-11-04 19:12:37,266 INFO MainThread :  * Running on http://127.0.0.1:5000/ (Press CTRL+C to quit)
2020-11-04 19:13:24,439 ERROR Thread-1 : Exception on /api/otb [GET]
Traceback (most recent call last):
  File "/mnt/c/Users/luisi/Desktop/cloe/api/env/lib/python3.7/site-packages/flask/app.py", line 2447, in wsgi_app
    response = self.full_dispatch_request()
  File "/mnt/c/Users/luisi/Desktop/cloe/api/env/lib/python3.7/site-packages/flask/app.py", line 1952, in full_dispatch_request
    rv = self.handle_user_exception(e)
  File "/mnt/c/Users/luisi/Desktop/cloe/api/env/lib/python3.7/site-packages/flask_cors/extension.py", line 165, in wrapped_function
    return cors_after_request(app.make_response(f(*args, **kwargs)))
  File "/mnt/c/Users/luisi/Desktop/cloe/api/env/lib/python3.7/site-packages/flask/app.py", line 1821, in handle_user_exception
    reraise(exc_type, exc_value, tb)
  File "/mnt/c/Users/luisi/Desktop/cloe/api/env/lib/python3.7/site-packages/flask/_compat.py", line 39, in reraise
    raise value
  File "/mnt/c/Users/luisi/Desktop/cloe/api/env/lib/python3.7/site-packages/flask/app.py", line 1950, in full_dispatch_request
    rv = self.dispatch_request()
  File "/mnt/c/Users/luisi/Desktop/cloe/api/env/lib/python3.7/site-packages/flask/app.py", line 1936, in dispatch_request
    return self.view_functions[rule.endpoint](**req.view_args)
  File "/mnt/c/Users/luisi/Desktop/cloe/api/env/lib/python3.7/site-packages/flask/views.py", line 89, in view
    return self.dispatch_request(*args, **kwargs)
  File "/mnt/c/Users/luisi/Desktop/cloe/api/env/lib/python3.7/site-packages/flask/views.py", line 163, in dispatch_request
    return meth(*args, **kwargs)
  File "/mnt/c/Users/luisi/Desktop/cloe/api/app/routes/otb.py", line 117, in get
    return make_response(jsonify(responseObject)), 200
  File "/mnt/c/Users/luisi/Desktop/cloe/api/env/lib/python3.7/site-packages/flask/json/__init__.py", line 370, in jsonify
    dumps(data, indent=indent, separators=separators) + "\n",
  File "/mnt/c/Users/luisi/Desktop/cloe/api/env/lib/python3.7/site-packages/flask/json/__init__.py", line 211, in dumps
    rv = _json.dumps(obj, **kwargs)
  File "/usr/lib/python3.7/json/__init__.py", line 238, in dumps
    **kw).encode(obj)
  File "/usr/lib/python3.7/json/encoder.py", line 199, in encode
    chunks = self.iterencode(o, _one_shot=True)
  File "/usr/lib/python3.7/json/encoder.py", line 257, in iterencode
    return _iterencode(o, 0)
  File "/mnt/c/Users/luisi/Desktop/cloe/api/env/lib/python3.7/site-packages/flask/json/__init__.py", line 100, in default
    return _json.JSONEncoder.default(self, o)
  File "/usr/lib/python3.7/json/encoder.py", line 179, in default
    raise TypeError(f'Object of type {o.__class__.__name__} '
TypeError: Object of type Decimal is not JSON serializable
2020-11-04 19:13:24,659 INFO Thread-1 : 127.0.0.1 - - [04/Nov/2020 19:13:24] "[35m[1mGET /api/otb?mercado=d&current_period=29-NOV-20 HTTP/1.1[0m" 500 -
2020-11-04 19:13:27,139 ERROR Thread-2 : Exception on /api/otb [GET]
Traceback (most recent call last):
  File "/mnt/c/Users/luisi/Desktop/cloe/api/env/lib/python3.7/site-packages/flask/app.py", line 2447, in wsgi_app
    response = self.full_dispatch_request()
  File "/mnt/c/Users/luisi/Desktop/cloe/api/env/lib/python3.7/site-packages/flask/app.py", line 1952, in full_dispatch_request
    rv = self.handle_user_exception(e)
  File "/mnt/c/Users/luisi/Desktop/cloe/api/env/lib/python3.7/site-packages/flask_cors/extension.py", line 165, in wrapped_function
    return cors_after_request(app.make_response(f(*args, **kwargs)))
  File "/mnt/c/Users/luisi/Desktop/cloe/api/env/lib/python3.7/site-packages/flask/app.py", line 1821, in handle_user_exception
    reraise(exc_type, exc_value, tb)
  File "/mnt/c/Users/luisi/Desktop/cloe/api/env/lib/python3.7/site-packages/flask/_compat.py", line 39, in reraise
    raise value
  File "/mnt/c/Users/luisi/Desktop/cloe/api/env/lib/python3.7/site-packages/flask/app.py", line 1950, in full_dispatch_request
    rv = self.dispatch_request()
  File "/mnt/c/Users/luisi/Desktop/cloe/api/env/lib/python3.7/site-packages/flask/app.py", line 1936, in dispatch_request
    return self.view_functions[rule.endpoint](**req.view_args)
  File "/mnt/c/Users/luisi/Desktop/cloe/api/env/lib/python3.7/site-packages/flask/views.py", line 89, in view
    return self.dispatch_request(*args, **kwargs)
  File "/mnt/c/Users/luisi/Desktop/cloe/api/env/lib/python3.7/site-packages/flask/views.py", line 163, in dispatch_request
    return meth(*args, **kwargs)
  File "/mnt/c/Users/luisi/Desktop/cloe/api/app/routes/otb.py", line 117, in get
    return make_response(jsonify(responseObject)), 200
  File "/mnt/c/Users/luisi/Desktop/cloe/api/env/lib/python3.7/site-packages/flask/json/__init__.py", line 370, in jsonify
    dumps(data, indent=indent, separators=separators) + "\n",
  File "/mnt/c/Users/luisi/Desktop/cloe/api/env/lib/python3.7/site-packages/flask/json/__init__.py", line 211, in dumps
    rv = _json.dumps(obj, **kwargs)
  File "/usr/lib/python3.7/json/__init__.py", line 238, in dumps
    **kw).encode(obj)
  File "/usr/lib/python3.7/json/encoder.py", line 199, in encode
    chunks = self.iterencode(o, _one_shot=True)
  File "/usr/lib/python3.7/json/encoder.py", line 257, in iterencode
    return _iterencode(o, 0)
  File "/mnt/c/Users/luisi/Desktop/cloe/api/env/lib/python3.7/site-packages/flask/json/__init__.py", line 100, in default
    return _json.JSONEncoder.default(self, o)
  File "/usr/lib/python3.7/json/encoder.py", line 179, in default
    raise TypeError(f'Object of type {o.__class__.__name__} '
TypeError: Object of type Decimal is not JSON serializable
2020-11-04 19:13:27,272 INFO Thread-2 : 127.0.0.1 - - [04/Nov/2020 19:13:27] "[35m[1mGET /api/otb?mercado=d&current_period=29-NOV-20 HTTP/1.1[0m" 500 -
2020-11-04 19:14:26,257 INFO MainThread :  * Running on http://127.0.0.1:5000/ (Press CTRL+C to quit)
2020-11-04 19:15:05,561 INFO MainThread :  * Running on http://127.0.0.1:5000/ (Press CTRL+C to quit)
