2020-11-07 15:37:54,669 INFO MainThread :  * Running on http://127.0.0.1:5000/ (Press CTRL+C to quit)
2020-11-07 15:38:00,671 ERROR Thread-1 : Exception on /api/otb/filters [GET]
Traceback (most recent call last):
  File "/mnt/c/Users/luisi/Desktop/cloe/api/env/lib/python3.7/site-packages/sqlalchemy/engine/base.py", line 1277, in _execute_context
    cursor, statement, parameters, context
  File "/mnt/c/Users/luisi/Desktop/cloe/api/env/lib/python3.7/site-packages/sqlalchemy/engine/default.py", line 593, in do_execute
    cursor.execute(statement, parameters)
cx_Oracle.DatabaseError: ORA-00904: "CATEGORIA": invalid identifier

The above exception was the direct cause of the following exception:

Traceback (most recent call last):
  File "/mnt/c/Users/luisi/Desktop/cloe/api/env/lib/python3.7/site-packages/flask/app.py", line 2447, in wsgi_app
    response = self.full_dispatch_request()
  File "/mnt/c/Users/luisi/Desktop/cloe/api/env/lib/python3.7/site-packages/flask/app.py", line 1952, in full_dispatch_request
    rv = self.handle_user_exception(e)
  File "/mnt/c/Users/luisi/Desktop/cloe/api/env/lib/python3.7/site-packages/flask_cors/extension.py", line 165, in wrapped_function
    return cors_after_request(app.make_response(f(*args, **kwargs)))
  File "/mnt/c/Users/luisi/Desktop/cloe/api/env/lib/python3.7/site-packages/flask/app.py", line 1821, in handle_user_exception
    reraise(exc_type, exc_value, tb)
  File "/mnt/c/Users/luisi/Desktop/cloe/api/env/lib/python3.7/site-packages/flask/_compat.py", line 39, in reraise
    raise value
  File "/mnt/c/Users/luisi/Desktop/cloe/api/env/lib/python3.7/site-packages/flask/app.py", line 1950, in full_dispatch_request
    rv = self.dispatch_request()
  File "/mnt/c/Users/luisi/Desktop/cloe/api/env/lib/python3.7/site-packages/flask/app.py", line 1936, in dispatch_request
    return self.view_functions[rule.endpoint](**req.view_args)
  File "/mnt/c/Users/luisi/Desktop/cloe/api/env/lib/python3.7/site-packages/flask/views.py", line 89, in view
    return self.dispatch_request(*args, **kwargs)
  File "/mnt/c/Users/luisi/Desktop/cloe/api/env/lib/python3.7/site-packages/flask/views.py", line 163, in dispatch_request
    return meth(*args, **kwargs)
  File "/mnt/c/Users/luisi/Desktop/cloe/api/app/routes/otb_filters.py", line 22, in get
    'categoria': self.get_by_filter('categoria'),
  File "/mnt/c/Users/luisi/Desktop/cloe/api/app/routes/otb_filters.py", line 12, in get_by_filter
    res_query = db.session.query(filter).group_by(filter).all()
  File "/mnt/c/Users/luisi/Desktop/cloe/api/env/lib/python3.7/site-packages/sqlalchemy/orm/query.py", line 3346, in all
    return list(self)
  File "/mnt/c/Users/luisi/Desktop/cloe/api/env/lib/python3.7/site-packages/sqlalchemy/orm/query.py", line 3508, in __iter__
    return self._execute_and_instances(context)
  File "/mnt/c/Users/luisi/Desktop/cloe/api/env/lib/python3.7/site-packages/sqlalchemy/orm/query.py", line 3533, in _execute_and_instances
    result = conn.execute(querycontext.statement, self._params)
  File "/mnt/c/Users/luisi/Desktop/cloe/api/env/lib/python3.7/site-packages/sqlalchemy/engine/base.py", line 1011, in execute
    return meth(self, multiparams, params)
  File "/mnt/c/Users/luisi/Desktop/cloe/api/env/lib/python3.7/site-packages/sqlalchemy/sql/elements.py", line 298, in _execute_on_connection
    return connection._execute_clauseelement(self, multiparams, params)
  File "/mnt/c/Users/luisi/Desktop/cloe/api/env/lib/python3.7/site-packages/sqlalchemy/engine/base.py", line 1130, in _execute_clauseelement
    distilled_params,
  File "/mnt/c/Users/luisi/Desktop/cloe/api/env/lib/python3.7/site-packages/sqlalchemy/engine/base.py", line 1317, in _execute_context
    e, statement, parameters, cursor, context
  File "/mnt/c/Users/luisi/Desktop/cloe/api/env/lib/python3.7/site-packages/sqlalchemy/engine/base.py", line 1511, in _handle_dbapi_exception
    sqlalchemy_exception, with_traceback=exc_info[2], from_=e
  File "/mnt/c/Users/luisi/Desktop/cloe/api/env/lib/python3.7/site-packages/sqlalchemy/util/compat.py", line 182, in raise_
    raise exception
  File "/mnt/c/Users/luisi/Desktop/cloe/api/env/lib/python3.7/site-packages/sqlalchemy/engine/base.py", line 1277, in _execute_context
    cursor, statement, parameters, context
  File "/mnt/c/Users/luisi/Desktop/cloe/api/env/lib/python3.7/site-packages/sqlalchemy/engine/default.py", line 593, in do_execute
    cursor.execute(statement, parameters)
sqlalchemy.exc.DatabaseError: (cx_Oracle.DatabaseError) ORA-00904: "CATEGORIA": invalid identifier
[SQL: SELECT categoria FROM DUAL GROUP BY categoria]
(Background on this error at: http://sqlalche.me/e/13/4xp6)
2020-11-07 15:38:00,829 INFO Thread-1 : 127.0.0.1 - - [07/Nov/2020 15:38:00] "[35m[1mGET /api/otb/filters HTTP/1.1[0m" 500 -
2020-11-07 15:41:17,380 INFO MainThread :  * Running on http://127.0.0.1:5000/ (Press CTRL+C to quit)
2020-11-07 15:41:20,396 ERROR Thread-1 : Exception on /api/otb/filters [GET]
Traceback (most recent call last):
  File "/mnt/c/Users/luisi/Desktop/cloe/api/env/lib/python3.7/site-packages/flask/app.py", line 2447, in wsgi_app
    response = self.full_dispatch_request()
  File "/mnt/c/Users/luisi/Desktop/cloe/api/env/lib/python3.7/site-packages/flask/app.py", line 1952, in full_dispatch_request
    rv = self.handle_user_exception(e)
  File "/mnt/c/Users/luisi/Desktop/cloe/api/env/lib/python3.7/site-packages/flask_cors/extension.py", line 165, in wrapped_function
    return cors_after_request(app.make_response(f(*args, **kwargs)))
  File "/mnt/c/Users/luisi/Desktop/cloe/api/env/lib/python3.7/site-packages/flask/app.py", line 1821, in handle_user_exception
    reraise(exc_type, exc_value, tb)
  File "/mnt/c/Users/luisi/Desktop/cloe/api/env/lib/python3.7/site-packages/flask/_compat.py", line 39, in reraise
    raise value
  File "/mnt/c/Users/luisi/Desktop/cloe/api/env/lib/python3.7/site-packages/flask/app.py", line 1950, in full_dispatch_request
    rv = self.dispatch_request()
  File "/mnt/c/Users/luisi/Desktop/cloe/api/env/lib/python3.7/site-packages/flask/app.py", line 1936, in dispatch_request
    return self.view_functions[rule.endpoint](**req.view_args)
  File "/mnt/c/Users/luisi/Desktop/cloe/api/env/lib/python3.7/site-packages/flask/views.py", line 89, in view
    return self.dispatch_request(*args, **kwargs)
  File "/mnt/c/Users/luisi/Desktop/cloe/api/env/lib/python3.7/site-packages/flask/views.py", line 163, in dispatch_request
    return meth(*args, **kwargs)
  File "/mnt/c/Users/luisi/Desktop/cloe/api/app/routes/otb_filters.py", line 22, in get
    'categoria': self.get_by_filter('categoria'),
  File "/mnt/c/Users/luisi/Desktop/cloe/api/app/routes/otb_filters.py", line 12, in get_by_filter
    res_query = OtbResults.query(filter).group_by(filter).all()
TypeError: 'BaseQuery' object is not callable
2020-11-07 15:41:20,436 INFO Thread-1 : 127.0.0.1 - - [07/Nov/2020 15:41:20] "[35m[1mGET /api/otb/filters HTTP/1.1[0m" 500 -
2020-11-07 15:43:09,801 INFO MainThread :  * Running on http://127.0.0.1:5000/ (Press CTRL+C to quit)
2020-11-07 15:43:30,184 ERROR Thread-1 : Exception on /api/otb/filters [GET]
Traceback (most recent call last):
  File "/mnt/c/Users/luisi/Desktop/cloe/api/env/lib/python3.7/site-packages/sqlalchemy/engine/base.py", line 1277, in _execute_context
    cursor, statement, parameters, context
  File "/mnt/c/Users/luisi/Desktop/cloe/api/env/lib/python3.7/site-packages/sqlalchemy/engine/default.py", line 593, in do_execute
    cursor.execute(statement, parameters)
cx_Oracle.DatabaseError: ORA-00904: "CATEGORIA": invalid identifier

The above exception was the direct cause of the following exception:

Traceback (most recent call last):
  File "/mnt/c/Users/luisi/Desktop/cloe/api/env/lib/python3.7/site-packages/flask/app.py", line 2447, in wsgi_app
    response = self.full_dispatch_request()
  File "/mnt/c/Users/luisi/Desktop/cloe/api/env/lib/python3.7/site-packages/flask/app.py", line 1952, in full_dispatch_request
    rv = self.handle_user_exception(e)
  File "/mnt/c/Users/luisi/Desktop/cloe/api/env/lib/python3.7/site-packages/flask_cors/extension.py", line 165, in wrapped_function
    return cors_after_request(app.make_response(f(*args, **kwargs)))
  File "/mnt/c/Users/luisi/Desktop/cloe/api/env/lib/python3.7/site-packages/flask/app.py", line 1821, in handle_user_exception
    reraise(exc_type, exc_value, tb)
  File "/mnt/c/Users/luisi/Desktop/cloe/api/env/lib/python3.7/site-packages/flask/_compat.py", line 39, in reraise
    raise value
  File "/mnt/c/Users/luisi/Desktop/cloe/api/env/lib/python3.7/site-packages/flask/app.py", line 1950, in full_dispatch_request
    rv = self.dispatch_request()
  File "/mnt/c/Users/luisi/Desktop/cloe/api/env/lib/python3.7/site-packages/flask/app.py", line 1936, in dispatch_request
    return self.view_functions[rule.endpoint](**req.view_args)
  File "/mnt/c/Users/luisi/Desktop/cloe/api/env/lib/python3.7/site-packages/flask/views.py", line 89, in view
    return self.dispatch_request(*args, **kwargs)
  File "/mnt/c/Users/luisi/Desktop/cloe/api/env/lib/python3.7/site-packages/flask/views.py", line 163, in dispatch_request
    return meth(*args, **kwargs)
  File "/mnt/c/Users/luisi/Desktop/cloe/api/app/routes/otb_filters.py", line 23, in get
    'categoria': self.get_by_filter('categoria'),
  File "/mnt/c/Users/luisi/Desktop/cloe/api/app/routes/otb_filters.py", line 13, in get_by_filter
    filter).group_by(filter).all()
  File "/mnt/c/Users/luisi/Desktop/cloe/api/env/lib/python3.7/site-packages/sqlalchemy/orm/query.py", line 3346, in all
    return list(self)
  File "/mnt/c/Users/luisi/Desktop/cloe/api/env/lib/python3.7/site-packages/sqlalchemy/orm/query.py", line 3508, in __iter__
    return self._execute_and_instances(context)
  File "/mnt/c/Users/luisi/Desktop/cloe/api/env/lib/python3.7/site-packages/sqlalchemy/orm/query.py", line 3533, in _execute_and_instances
    result = conn.execute(querycontext.statement, self._params)
  File "/mnt/c/Users/luisi/Desktop/cloe/api/env/lib/python3.7/site-packages/sqlalchemy/engine/base.py", line 1011, in execute
    return meth(self, multiparams, params)
  File "/mnt/c/Users/luisi/Desktop/cloe/api/env/lib/python3.7/site-packages/sqlalchemy/sql/elements.py", line 298, in _execute_on_connection
    return connection._execute_clauseelement(self, multiparams, params)
  File "/mnt/c/Users/luisi/Desktop/cloe/api/env/lib/python3.7/site-packages/sqlalchemy/engine/base.py", line 1130, in _execute_clauseelement
    distilled_params,
  File "/mnt/c/Users/luisi/Desktop/cloe/api/env/lib/python3.7/site-packages/sqlalchemy/engine/base.py", line 1317, in _execute_context
    e, statement, parameters, cursor, context
  File "/mnt/c/Users/luisi/Desktop/cloe/api/env/lib/python3.7/site-packages/sqlalchemy/engine/base.py", line 1511, in _handle_dbapi_exception
    sqlalchemy_exception, with_traceback=exc_info[2], from_=e
  File "/mnt/c/Users/luisi/Desktop/cloe/api/env/lib/python3.7/site-packages/sqlalchemy/util/compat.py", line 182, in raise_
    raise exception
  File "/mnt/c/Users/luisi/Desktop/cloe/api/env/lib/python3.7/site-packages/sqlalchemy/engine/base.py", line 1277, in _execute_context
    cursor, statement, parameters, context
  File "/mnt/c/Users/luisi/Desktop/cloe/api/env/lib/python3.7/site-packages/sqlalchemy/engine/default.py", line 593, in do_execute
    cursor.execute(statement, parameters)
sqlalchemy.exc.DatabaseError: (cx_Oracle.DatabaseError) ORA-00904: "CATEGORIA": invalid identifier
[SQL: SELECT categoria FROM DUAL GROUP BY categoria]
(Background on this error at: http://sqlalche.me/e/13/4xp6)
2020-11-07 15:43:30,336 INFO Thread-1 : 127.0.0.1 - - [07/Nov/2020 15:43:30] "[35m[1mGET /api/otb/filters HTTP/1.1[0m" 500 -
